Workbook
Name __xlnm.Print_Area_3: #REF!
Name __xlnm.Print_Area_3: #REF!
Name __xlnm.Print_Area_4: #REF!
Name IP_PBX: #REF!
Name IP_PBX: #REF!
Name OLE_LINK1: #REF!
Name Type: #REF!
Name Type: #REF!

Sheet Summary
D1: การจัดซื้ออุปกรณ์พร้อมดำเนินการติดตั้ง โครงการเพิ่มประสิทธิภาพระบบโครงข่ายสื่อสารด้วยอุปกรณ์ทวนสัญญาณผ่านคลื่นความถี่สูง (SHF) เพื่อสนับสนุนการปฏิบัติราชการและแก้ไขปัญหาให้กับประชาชนในพื้นที่ห่างไกล สัญญาเลขที่ ๘๖๘๐๒๒๘ ลงวันที่ ๒๓ กรกฎาคม ๒๕๖๘
B3: รายงานสรุปสถานะระบบชุมสายประจำวัน / DAILY SYSTEM STATUS REPORT
B4: วันที่ | C4: =TODAY() -> 46301
B5: ภาพรวมสถานะบริการทั้งระบบ
B6: ระบบศูนย์ควบคุมสถานีแม่ข่าย / Base Station Switching Center | F6: ระบบบริหารจัดการ (iMaster NCE Campus) / SD-WAN Controller | J6: ระบบบริหารจัดการชุดอุปกรณ์ทวนสัญญาณผ่านคลื่นความถี่สูง (iMaster NCE-T) / Microwave | N6: ชุดสั่งการ / Dispatcher
B7: =" สถานะ : "&Overview!$W$3 -> สถานะ : ปกติ / Normal | F7: =" สถานะ : "&Overview!$W$4 -> สถานะ : ปกติ / Normal | J7: =" สถานะ : "&Overview!$W$5 -> สถานะ : ปกติ / Normal | N7: =" สถานะ : "&Overview!$W$6 -> สถานะ : ปกติ / Normal
B9: สรุปงาน
B10: หัวข้อ | F10: ผลตรวจสอบ / Result | J10: ข้อความสรุป
B11: สถานะระบบรวม / Overall system status | F11: =IF(COUNTIF(Overview!$W$3:$W$6,"ขัดข้อง / Down")=0,"ปกติ / Normal","มีเหตุขัดข้อง / Down") -> ปกติ / Normal | J11: =IF(COUNTIF(Overview!$W$3:$W$5,"Down / ขัดข้อง")=0,"ระบบให้บริการตามปกติ / All systems operate normally","Action required: see system status sheet / มีระบบที่ต้องเร่งตรวจสอบ โปรดดูชีตข้อมูลสถานะระบบ") -> ระบบให้บริการตามปกติ / All systems operate normally
B12: รายการตรวจสอบสถานีปลายทาง / Station checks | F12: =COUNTA(Overview!$A$5:$A$20)&" จุด " -> 16 จุด | J12: ตรวจสอบสถานีและอุปกรณ์ตามรายการรายวัน / Station and equipment monitoring completed
B13: รายการรอแก้ไข / Pending corrections | F13: =Overview!$Q21&" รายการ / items" -> 1 รายการ / items | J13: =IF(Overview!$Q21=0,"ไม่มีรายการรอแก้ไข / No pending","มีรายการติดตามในชีตรายละเอียดจุดตรวจสอบ / See Station Details for follow-up") -> มีรายการติดตามในชีตรายละเอียดจุดตรวจสอบ / See Station Details for follow-up

Sheet Overview
A1: รายละเอียดผลการตรวจสอบสถานีและอุปกรณ์ชุมสาย / STATION & EQUIPMENT CHECK DETAILS | T1: ข้อมูลสถานะระบบ /SYSTEM STATUS INPUT
A2: ลำดับ | B2: ชื่อสถานี | C2: ไฟฟ้า | D2: สถานีแม่ข่าย | H2: อุปกรณ์กระจายสัญญาณ | K2: SD-WAN | M2: Microwave | O2: LINK | Q2: กำลังรอการแก้ไข | R2: หมายเหตุ | T2: No. / ลำดับ | U2: System / ระบบ | V2: Monitoring scope / ขอบเขตการตรวจสอบ | W2: Status / สถานะ | X2: Customer message / ข้อความสำหรับแจ้งลูกค้า | Y2: ปรับปรุงล่าสุด / Updated
C3: Electric | D3: VSWR > 1.5 | E3: Tx | F3: Rx | G3: Down | H3: CPRI Cable | I3: SFP | J3: Down | K3: Not stable | L3: Down | M3: Not stable | N3: Down | O3: Not stable | P3: Down | T3: 1 | U3: BSSC | V3: ระบบศูนย์ควบคุมสถานีแม่ข่าย (Base Station Switching Center) | W3: ปกติ / Normal | X3: ให้บริการตามปกติ ไม่พบเหตุขัดข้อง / Normal operation; no incident found
A4: =SUBTOTAL(3,A5:A20) -> 16 | B4: =SUBTOTAL(3,B5:B30) -> 16 | C4: =SUBTOTAL(2,C5:C30) -> 0 | D4: =SUBTOTAL(2,D5:D30) -> 0 | E4: =SUBTOTAL(2,E5:E30) -> 0 | F4: =SUBTOTAL(2,F5:F30) -> 0 | G4: =SUBTOTAL(2,G5:G30) -> 0 | H4: =SUBTOTAL(2,H5:H30) -> 0 | I4: =SUBTOTAL(2,I5:I30) -> 0 | J4: =SUBTOTAL(2,J5:J30) -> 0 | ... P4: =SUBTOTAL(2,P5:P30) -> 0 | Q4: 0 | T4: 2 | U4: SD-WAN | V4: ระบบบริหารจัดการ (iMaster NCE Campus) | W4: ปกติ / Normal | X4: ให้บริการตามปกติ ไม่พบเหตุขัดข้อง / Normal operation; no incident found
A5: BS-261 | B5: BS หนองนกแก้ว | C5: FALSE | D5: FALSE | E5: FALSE | F5: FALSE | G5: FALSE | H5: FALSE | I5: FALSE | J5: FALSE | K5: FALSE | L5: FALSE | M5: FALSE | N5: FALSE | O5: FALSE | P5: FALSE | Q5: =IF(COUNTIF(C5:P5,TRUE)=0,"",COUNTIF(C5:P5,TRUE)) | T5: 3 | U5: Microwave | V5: ระบบบริหารจัดการชุดอุปกรณ์ทวนสัญญาณผ่านคลื่นความถี่สูง (iMaster NCE-T) | W5: ปกติ / Normal | X5: ให้บริการตามปกติ ไม่พบเหตุขัดข้อง / Normal operation; no incident found
A6: BS-262 | B6: BS ศรีสุขสำราญ | C6: FALSE | D6: FALSE | E6: FALSE | F6: FALSE | G6: FALSE | H6: FALSE | I6: FALSE | J6: FALSE | K6: FALSE | L6: FALSE | M6: FALSE | N6: FALSE | O6: FALSE | P6: FALSE | Q6: =IF(COUNTIF(C6:P6,TRUE)=0,"",COUNTIF(C6:P6,TRUE)) | T6: 4 | U6: Dispatcher | V6: ชุดสั่งการ | W6: ปกติ / Normal | X6: ให้บริการตามปกติ ไม่พบเหตุขัดข้อง / Normal operation; no incident found
A7: BS-263 | B7: BS บ้านคลองป่าหมู | C7: FALSE | D7: FALSE | E7: FALSE | F7: FALSE | G7: FALSE | H7: FALSE | I7: FALSE | J7: FALSE | K7: FALSE | L7: FALSE | M7: FALSE | N7: FALSE | O7: FALSE | P7: FALSE | Q7: =IF(COUNTIF(C7:P7,TRUE)=0,"",COUNTIF(C7:P7,TRUE)) | T7: Base station 8 station | U7: จำนวน
A8: BS-264 | B8: BS วัดบางอุดม | C8: FALSE | D8: FALSE | E8: FALSE | F8: FALSE | G8: FALSE | H8: FALSE | I8: FALSE | J8: FALSE | K8: FALSE | L8: FALSE | M8: FALSE | N8: FALSE | O8: FALSE | P8: FALSE | Q8: =IF(COUNTIF(C8:P8,TRUE)=0,"",COUNTIF(C8:P8,TRUE)) | T8: Online | U8: =COUNTBLANK(Q5:Q12) -> 7
A9: BS-265 | B9: BS วังงิ้ว | C9: TRUE | D9: FALSE | E9: FALSE | F9: FALSE | G9: TRUE | H9: FALSE | I9: FALSE | J9: FALSE | K9: FALSE | L9: FALSE | M9: FALSE | N9: TRUE | O9: FALSE | P9: FALSE | Q9: =IF(COUNTIF(C9:P9,TRUE)=0,"",COUNTIF(C9:P9,TRUE)) -> 3 | T9: Pending | U9: =ROWS(Q5:Q12)-COUNTBLANK(Q5:Q12) -> 1
A10: BS-266 | B10: BS บ้านปางใหม่พัฒนา | C10: FALSE | D10: FALSE | E10: FALSE | F10: FALSE | G10: FALSE | H10: FALSE | I10: FALSE | J10: FALSE | K10: FALSE | L10: FALSE | M10: FALSE | N10: FALSE | O10: FALSE | P10: FALSE | Q10: =IF(COUNTIF(C10:P10,TRUE)=0,"",COUNTIF(C10:P10,TRUE)) | T10: Analog Gateway 8 station | U10: จำนวน
A11: BS-267 | B11: BS ช่อง | C11: FALSE | D11: FALSE | E11: FALSE | F11: FALSE | G11: FALSE | H11: FALSE | I11: FALSE | J11: FALSE | K11: FALSE | L11: FALSE | M11: FALSE | N11: FALSE | O11: FALSE | P11: FALSE | Q11: =IF(COUNTIF(C11:P11,TRUE)=0,"",COUNTIF(C11:P11,TRUE)) | T11: Online | U11: =COUNTBLANK(Q13:Q20) -> 8
A12: BS-268 | B12: BS คลองพลู | C12: FALSE | D12: FALSE | E12: FALSE | F12: FALSE | G12: FALSE | H12: FALSE | I12: FALSE | J12: FALSE | K12: FALSE | L12: FALSE | M12: FALSE | N12: FALSE | O12: FALSE | P12: FALSE | Q12: =IF(COUNTIF(C12:P12,TRUE)=0,"",COUNTIF(C12:P12,TRUE)) | T12: Pending | U12: =ROWS(Q13:Q20)-COUNTBLANK(Q13:Q20) -> 0
A13: AGW | B13: ที่ว่าการอำเภอห้วยกระเจา | C13: FALSE | D13: FALSE | E13: FALSE | F13: FALSE | G13: FALSE | H13: FALSE | I13: FALSE | J13: FALSE | K13: FALSE | L13: FALSE | M13: FALSE | N13: FALSE | O13: FALSE | P13: FALSE | Q13: =IF(COUNTIF(C13:P13,TRUE)=0,"",COUNTIF(C13:P13,TRUE))
A14: AGW | B14: ที่ว่าการอำเภอคลองลาน | C14: FALSE | D14: FALSE | E14: FALSE | F14: FALSE | G14: FALSE | H14: FALSE | I14: FALSE | J14: FALSE | K14: FALSE | L14: FALSE | M14: FALSE | N14: FALSE | O14: FALSE | P14: FALSE | Q14: =IF(COUNTIF(C14:P14,TRUE)=0,"",COUNTIF(C14:P14,TRUE))
A15: AGW | B15: ที่ว่าการอำเภอเขาสวนกวาง | C15: FALSE | D15: FALSE | E15: FALSE | F15: FALSE | G15: FALSE | H15: FALSE | I15: FALSE | J15: FALSE | K15: FALSE | L15: FALSE | M15: FALSE | N15: FALSE | O15: FALSE | P15: FALSE | Q15: =IF(COUNTIF(C15:P15,TRUE)=0,"",COUNTIF(C15:P15,TRUE))
A16: AGW | B16: ที่ว่าการอำเภอเขาคิชฌกูฎ | C16: FALSE | D16: FALSE | E16: FALSE | F16: FALSE | G16: FALSE | H16: FALSE | I16: FALSE | J16: FALSE | K16: FALSE | L16: FALSE | M16: FALSE | N16: FALSE | O16: FALSE | P16: FALSE | Q16: =IF(COUNTIF(C16:P16,TRUE)=0,"",COUNTIF(C16:P16,TRUE))
A17: AGW | B17: ที่ว่าการอำเภอย่านตาขาว | C17: FALSE | D17: FALSE | E17: FALSE | F17: FALSE | G17: FALSE | H17: FALSE | I17: FALSE | J17: FALSE | K17: FALSE | L17: FALSE | M17: FALSE | N17: FALSE | O17: FALSE | P17: FALSE | Q17: =IF(COUNTIF(C17:P17,TRUE)=0,"",COUNTIF(C17:P17,TRUE))
A18: AGW | B18: ที่ว่าการอำเภอวังน้ำเขียว | C18: FALSE | D18: FALSE | E18: FALSE | F18: FALSE | G18: FALSE | H18: FALSE | I18: FALSE | J18: FALSE | K18: FALSE | L18: FALSE | M18: FALSE | N18: FALSE | O18: FALSE | P18: FALSE | Q18: =IF(COUNTIF(C18:P18,TRUE)=0,"",COUNTIF(C18:P18,TRUE))
A19: AGW | B19: ที่ว่าการอำเภอหัวไทร | C19: FALSE | D19: FALSE | E19: FALSE | F19: FALSE | G19: FALSE | H19: FALSE | I19: FALSE | J19: FALSE | K19: FALSE | L19: FALSE | M19: FALSE | N19: FALSE | O19: FALSE | P19: FALSE | Q19: =IF(COUNTIF(C19:P19,TRUE)=0,"",COUNTIF(C19:P19,TRUE))
A20: AGW | B20: ที่ว่าการอำเภอดงเจริญ | C20: FALSE | D20: FALSE | E20: FALSE | F20: FALSE | G20: FALSE | H20: FALSE | I20: FALSE | J20: FALSE | K20: FALSE | L20: FALSE | M20: FALSE | N20: FALSE | O20: FALSE | P20: FALSE | Q20: =IF(COUNTIF(C20:P20,TRUE)=0,"",COUNTIF(C20:P20,TRUE))
A21: *** หมายเหตุ เช็คในช่องด้านบนเมื่อมีเหตุให้แก้ไขหรือพบข้อบกพร่อง | Q21: =SUBTOTAL(2,Q5:Q20) -> 1

Sheet Fixed Station
A1: ลำดับ TOR | B1: หมู่บ้าน | C1: ตำบล | D1: อำเภอ | E1: จังหวัด | F1: สถานะ OFLINE
A2: 1 | B2: หมู่ 13 หนองจิกน้ำดำ | C2: ทุ่งกระบ่ำ | D2: เลาขวัญ | E2: กาญจนบุรี | F2: FALSE
A3: 2 | B3: หมู่ 6 สี่กั๊ก | C3: ทุ่งกระบ่ำ | D3: เลาขวัญ | E3: กาญจนบุรี | F3: FALSE
A4: 3 | B4: หมู่ 7 หนองปลิง | C4: ทุ่งกระบ่ำ | D4: เลาขวัญ | E4: กาญจนบุรี | F4: FALSE
A5: 4 | B5: หมู่ 8 ชัฎดงพลับ | C5: ทุ่งกระบ่ำ | D5: เลาขวัญ | E5: กาญจนบุรี | F5: FALSE
A6: 5 | B6: หมู่ 2 หนองเค็ด | C6: หนองนกแก้ว | D6: เลาขวัญ | E6: กาญจนบุรี | F6: FALSE
A7: 6 | B7: หมู่ 4 หนองจั่น | C7: หนองนกแก้ว | D7: เลาขวัญ | E7: กาญจนบุรี | F7: FALSE
A8: 7 | B8: หมู่ 5 หนองขบ | C8: หนองนกแก้ว | D8: เลาขวัญ | E8: กาญจนบุรี | F8: FALSE
A9: 8 | B9: หมู่ 9 หนองข่อย | C9: หนองนกแก้ว | D9: เลาขวัญ | E9: กาญจนบุรี | F9: FALSE
A10: 9 | B10: หมู่ 10 หนองมะสังข์ | C10: หนองประดู่ | D10: เลาขวัญ | E10: กาญจนบุรี | F10: FALSE
A11: 10 | B11: หมู่ 11 หนองตาเกิด | C11: หนองประดู่ | D11: เลาขวัญ | E11: กาญจนบุรี | F11: FALSE
A12: 11 | B12: หมู่ 3 ตลุงเหนือ | C12: หนองประดู่ | D12: เลาขวัญ | E12: กาญจนบุรี | F12: FALSE
A13: 12 | B13: หมู่ 5 หนองปรือ | C13: หนองประดู่ | D13: เลาขวัญ | E13: กาญจนบุรี | F13: FALSE
... A182: 181 | B182: หมู่ 8 ลำประสาน | C182: บัววัฒนา | D182: หนองไผ่ | E182: เพชรบูรณ์ | F182: FALSE

Sheet Event Log
A1: System | B1: Date | C1: Online (100%) | D1: Down time(min)
A2: BSSC | B2: 46235 | C2: =IF(D2="",100,MAX(0,(1440-D2)/1440*100)) -> 100
A3: BSSC | B3: 46236 | C3: =IF(D3="",100,MAX(0,(1440-D3)/1440*100)) -> 100
A4: BSSC | B4: 46237 | C4: =IF(D4="",100,MAX(0,(1440-D4)/1440*100)) -> 100
A5: BSSC | B5: 46238 | C5: =IF(D5="",100,MAX(0,(1440-D5)/1440*100)) -> 100
A6: BSSC | B6: 46239 | C6: =IF(D6="",100,MAX(0,(1440-D6)/1440*100)) -> 100
A7: BSSC | B7: 46240 | C7: =IF(D7="",100,MAX(0,(1440-D7)/1440*100)) -> 100
A8: BSSC | B8: 46241 | C8: =IF(D8="",100,MAX(0,(1440-D8)/1440*100)) -> 99.791667 | D8: 3
A9: BSSC | B9: 46242 | C9: =IF(D9="",100,MAX(0,(1440-D9)/1440*100)) -> 100
A10: BSSC | B10: 46243 | C10: =IF(D10="",100,MAX(0,(1440-D10)/1440*100)) -> 100
A11: BSSC | B11: 46244 | C11: =IF(D11="",100,MAX(0,(1440-D11)/1440*100)) -> 100
A12: BSSC | B12: 46245 | C12: =IF(D12="",100,MAX(0,(1440-D12)/1440*100)) -> 100
A13: BSSC | B13: 46246 | C13: =IF(D13="",100,MAX(0,(1440-D13)/1440*100)) -> 100
A14: BSSC | B14: 46247 | C14: =IF(D14="",100,MAX(0,(1440-D14)/1440*100)) -> 100
A15: BSSC | B15: 46248 | C15: =IF(D15="",100,MAX(0,(1440-D15)/1440*100)) -> 100
A16: BSSC | B16: 46249 | C16: =IF(D16="",100,MAX(0,(1440-D16)/1440*100)) -> 100
A17: BSSC | B17: 46250 | C17: =IF(D17="",100,MAX(0,(1440-D17)/1440*100)) -> 100
A18: BSSC | B18: 46251 | C18: =IF(D18="",100,MAX(0,(1440-D18)/1440*100)) -> 100
A19: BSSC | B19: 46252 | C19: =IF(D19="",100,MAX(0,(1440-D19)/1440*100)) -> 100
A20: BSSC | B20: 46253 | C20: =IF(D20="",100,MAX(0,(1440-D20)/1440*100)) -> 100
... A31: BSSC | B31: 46264 | C31: =IF(D31="",100,MAX(0,(1440-D31)/1440*100)) -> 100
A32: BSSC | B32: 46265 | C32: =IF(D32="",100,MAX(0,(1440-D32)/1440*100)) -> 99.722222 | D32: 4
A33: SD-WAN | B33: 46235 | C33: =IF(D33="",100,MAX(0,(1440-D33)/1440*100)) -> 100
A34: SD-WAN | B34: 46236 | C34: =IF(D34="",100,MAX(0,(1440-D34)/1440*100)) -> 100
A35: SD-WAN | B35: 46237 | C35: =IF(D35="",100,MAX(0,(1440-D35)/1440*100)) -> 100
A36: SD-WAN | B36: 46238 | C36: =IF(D36="",100,MAX(0,(1440-D36)/1440*100)) -> 100
A37: SD-WAN | B37: 46239 | C37: =IF(D37="",100,MAX(0,(1440-D37)/1440*100)) -> 100
A38: SD-WAN | B38: 46240 | C38: =IF(D38="",100,MAX(0,(1440-D38)/1440*100)) -> 100
A39: SD-WAN | B39: 46241 | C39: =IF(D39="",100,MAX(0,(1440-D39)/1440*100)) -> 100
A40: SD-WAN | B40: 46242 | C40: =IF(D40="",100,MAX(0,(1440-D40)/1440*100)) -> 100
A41: SD-WAN | B41: 46243 | C41: =IF(D41="",100,MAX(0,(1440-D41)/1440*100)) -> 100
A42: SD-WAN | B42: 46244 | C42: =IF(D42="",100,MAX(0,(1440-D42)/1440*100)) -> 100
A43: SD-WAN | B43: 46245 | C43: =IF(D43="",100,MAX(0,(1440-D43)/1440*100)) -> 100
A44: SD-WAN | B44: 46246 | C44: =IF(D44="",100,MAX(0,(1440-D44)/1440*100)) -> 100
... A66: Microwave | B66: 46237 | C66: =IF(D66="",100,MAX(0,(1440-D66)/1440*100)) -> 100
A67: Microwave | B67: 46238 | C67: =IF(D67="",100,MAX(0,(1440-D67)/1440*100)) -> 99.652778 | D67: 5
A68: Microwave | B68: 46239 | C68: =IF(D68="",100,MAX(0,(1440-D68)/1440*100)) -> 100
A69: Microwave | B69: 46240 | C69: =IF(D69="",100,MAX(0,(1440-D69)/1440*100)) -> 100
A70: Microwave | B70: 46241 | C70: =IF(D70="",100,MAX(0,(1440-D70)/1440*100)) -> 100
A71: Microwave | B71: 46242 | C71: =IF(D71="",100,MAX(0,(1440-D71)/1440*100)) -> 100
...
