Workbook
Name __xlnm.Print_Area_3: #REF!
Name __xlnm.Print_Area_3: #REF!
Name __xlnm.Print_Area_4: #REF!
Name IP_PBX: #REF!
Name IP_PBX: #REF!
Name OLE_LINK1: #REF!
Name Type: #REF!
Name Type: #REF!

Sheet รายงานสรุป
D3: การจัดซื้ออุปกรณ์พร้อมดำเนินการติดตั้ง โครงการเพิ่มประสิทธิภาพระบบโครงข่ายสื่อสารด้วยอุปกรณ์ทวนสัญญาณผ่านคลื่นความถี่สูง (SHF) เพื่อสนับสนุนการปฏิบัติราชการและแก้ไขปัญหาให้กับประชาชนในพื้นที่ห่างไกล สัญญาเลขที่ ๘๖๘๐๒๒๘ ลงวันที่ ๒๓ กรกฎาคม ๒๕๖๘
B5: รายงานสรุปสถานะระบบชุมสายประจำวัน / DAILY SYSTEM STATUS REPORT
B6: วันที่ | C6: =TODAY() -> 46266
B7: ภาพรวมสถานะบริการทั้งระบบ
B8: ระบบศูนย์ควบคุมสถานีแม่ข่าย / Base Station Switching Center | F8: ระบบบริหารจัดการ (iMaster NCE Campus) / SD-WAN Controller | J8: ระบบบริหารจัดการชุดอุปกรณ์ทวนสัญญาณผ่านคลื่นความถี่สูง (iMaster NCE-T) / Microwave | N8: ชุดสั่งการ / Dispatcher
B9: =" สถานะ : "&Overview!$W$3 -> สถานะ : ขัดข้อง / Down | F9: =" สถานะ : "&Overview!$W$4 -> สถานะ : ปกติ / Normal | J9: =" สถานะ : "&Overview!$W$5 -> สถานะ : ปกติ / Normal | N9: =" สถานะ : "&Overview!$W$6 -> สถานะ : ปกติ / Normal
B11: สรุปงาน
B12: หัวข้อ | F12: ผลตรวจสอบ / Result | J12: ข้อความสรุป
B13: สถานะระบบรวม / Overall system status | F13: =IF(COUNTIF(Overview!$W$3:$W$6,"ขัดข้อง / Down")=0,"ปกติ / Normal","มีเหตุขัดข้อง / Down") -> มีเหตุขัดข้อง / Down | J13: =IF(COUNTIF(Overview!$W$3:$W$5,"Down / ขัดข้อง")=0,"ระบบให้บริการตามปกติ / All systems operate normally","Action required: see system status sheet / มีระบบที่ต้องเร่งตรวจสอบ โปรดดูชีตข้อมูลสถานะระบบ") -> ระบบให้บริการตามปกติ / All systems operate normally
B14: รายการตรวจสอบสถานีปลายทาง / Station checks | F14: =COUNTA(Overview!$A$5:$A$20)&" จุด " -> 16 จุด | J14: ตรวจสอบสถานีและอุปกรณ์ตามรายการรายวัน / Station and equipment monitoring completed
B15: รายการรอแก้ไข / Pending corrections | F15: =Overview!$Q21&" รายการ / items" -> 0 รายการ / items | J15: =IF(Overview!$Q21=0,"ไม่มีรายการรอแก้ไข / No pending","มีรายการติดตามในชีตรายละเอียดจุดตรวจสอบ / See Station Details for follow-up") -> ไม่มีรายการรอแก้ไข / No pending

Sheet Overview
A1: รายละเอียดผลการตรวจสอบสถานีและอุปกรณ์ชุมสาย / STATION & EQUIPMENT CHECK DETAILS | T1: ข้อมูลสถานะระบบ /SYSTEM STATUS INPUT
A2: ลำดับ | B2: ชื่อสถานี | C2: ไฟฟ้า | D2: สถานีแม่ข่าย | H2: อุปกรณ์กระจายสัญญาณ | K2: SD-WAN | M2: Microwave | O2: LINK | Q2: กำลังรอการแก้ไข | R2: หมายเหตุ | T2: No. / ลำดับ | U2: System / ระบบ | V2: Monitoring scope / ขอบเขตการตรวจสอบ | W2: Status / สถานะ | X2: Customer message / ข้อความสำหรับแจ้งลูกค้า | Y2: ปรับปรุงล่าสุด / Updated
C3: Electric | D3: VSWR > 1.5 | E3: Tx | F3: Rx | G3: Down | H3: CPRI Cable | I3: SFP | J3: Down | K3: Not stable | L3: Down | M3: Not stable | N3: Down | O3: Not stable | P3: Down | T3: 1 | U3: BSSC | V3: ระบบศูนย์ควบคุมสถานีแม่ข่าย (Base Station Switching Center) | W3: ขัดข้อง / Down | X3: ให้บริการตามปกติ ไม่พบเหตุขัดข้อง / Normal operation; no incident found
A4: =SUBTOTAL(3,A5:A20) -> 16 | B4: =SUBTOTAL(3,B5:B30) -> 16 | C4: =SUBTOTAL(2,C5:C30) -> 0 | D4: =SUBTOTAL(2,D5:D30) -> 0 | E4: =SUBTOTAL(2,E5:E30) -> 0 | F4: =SUBTOTAL(2,F5:F30) -> 0 | G4: =SUBTOTAL(2,G5:G30) -> 0 | H4: =SUBTOTAL(2,H5:H30) -> 0 | I4: =SUBTOTAL(2,I5:I30) -> 0 | J4: =SUBTOTAL(2,J5:J30) -> 0 | ... P4: =SUBTOTAL(2,P5:P30) -> 0 | Q4: 0 | T4: 2 | U4: SD-WAN | V4: ระบบบริหารจัดการ (iMaster NCE Campus) | W4: ปกติ / Normal | X4: ให้บริการตามปกติ ไม่พบเหตุขัดข้อง / Normal operation; no incident found
A5: BS-261 | B5: BS หนองนกแก้ว | C5: FALSE | D5: FALSE | E5: FALSE | F5: FALSE | G5: FALSE | H5: FALSE | I5: FALSE | J5: FALSE | K5: FALSE | L5: FALSE | M5: FALSE | N5: FALSE | O5: FALSE | P5: FALSE | Q5: =IF(COUNTIF(C5:P5,TRUE)=0,"",COUNTIF(C5:P5,TRUE)) | T5: 3 | U5: Microwave | V5: ระบบบริหารจัดการชุดอุปกรณ์ทวนสัญญาณผ่านคลื่นความถี่สูง (iMaster NCE-T) | W5: ปกติ / Normal | X5: ให้บริการตามปกติ ไม่พบเหตุขัดข้อง / Normal operation; no incident found
A6: BS-262 | B6: BS ศรีสุขสำราญ | C6: FALSE | D6: FALSE | E6: FALSE | F6: FALSE | G6: FALSE | H6: FALSE | I6: FALSE | J6: FALSE | K6: FALSE | L6: FALSE | M6: FALSE | N6: FALSE | O6: FALSE | P6: FALSE | Q6: =IF(COUNTIF(C6:P6,TRUE)=0,"",COUNTIF(C6:P6,TRUE)) | T6: 4 | U6: Dispatcher | V6: ชุดสั่งการ | W6: ปกติ / Normal | X6: ให้บริการตามปกติ ไม่พบเหตุขัดข้อง / Normal operation; no incident found
A7: BS-263 | B7: BS คลองป่าหมู | C7: FALSE | D7: FALSE | E7: FALSE | F7: FALSE | G7: FALSE | H7: FALSE | I7: FALSE | J7: FALSE | K7: FALSE | L7: FALSE | M7: FALSE | N7: FALSE | O7: FALSE | P7: FALSE | Q7: =IF(COUNTIF(C7:P7,TRUE)=0,"",COUNTIF(C7:P7,TRUE))
A8: BS-264 | B8: BS วััดบางอุดม | C8: FALSE | D8: FALSE | E8: FALSE | F8: FALSE | G8: FALSE | H8: FALSE | I8: FALSE | J8: FALSE | K8: FALSE | L8: FALSE | M8: FALSE | N8: FALSE | O8: FALSE | P8: FALSE | Q8: =IF(COUNTIF(C8:P8,TRUE)=0,"",COUNTIF(C8:P8,TRUE))
A9: BS-265 | B9: BS วังงิ้ว | C9: FALSE | D9: FALSE | E9: FALSE | F9: FALSE | G9: FALSE | H9: FALSE | I9: FALSE | J9: FALSE | K9: FALSE | L9: FALSE | M9: FALSE | N9: FALSE | O9: FALSE | P9: FALSE | Q9: =IF(COUNTIF(C9:P9,TRUE)=0,"",COUNTIF(C9:P9,TRUE))
A10: BS-266 | B10: BS บ้านปางใหม่พัฒนา | C10: FALSE | D10: FALSE | E10: FALSE | F10: FALSE | G10: FALSE | H10: FALSE | I10: FALSE | J10: FALSE | K10: FALSE | L10: FALSE | M10: FALSE | N10: FALSE | O10: FALSE | P10: FALSE | Q10: =IF(COUNTIF(C10:P10,TRUE)=0,"",COUNTIF(C10:P10,TRUE))
A11: BS-267 | B11: BS ช่อง | C11: FALSE | D11: FALSE | E11: FALSE | F11: FALSE | G11: FALSE | H11: FALSE | I11: FALSE | J11: FALSE | K11: FALSE | L11: FALSE | M11: FALSE | N11: FALSE | O11: FALSE | P11: FALSE | Q11: =IF(COUNTIF(C11:P11,TRUE)=0,"",COUNTIF(C11:P11,TRUE))
A12: BS-268 | B12: BS คลองพลู | C12: FALSE | D12: FALSE | E12: FALSE | F12: FALSE | G12: FALSE | H12: FALSE | I12: FALSE | J12: FALSE | K12: FALSE | L12: FALSE | M12: FALSE | N12: FALSE | O12: FALSE | P12: FALSE | Q12: =IF(COUNTIF(C12:P12,TRUE)=0,"",COUNTIF(C12:P12,TRUE))
A13: AGW | B13: ห้วยกระเจา | C13: FALSE | D13: FALSE | E13: FALSE | F13: FALSE | G13: FALSE | H13: FALSE | I13: FALSE | J13: FALSE | K13: FALSE | L13: FALSE | M13: FALSE | N13: FALSE | O13: FALSE | P13: FALSE | Q13: =IF(COUNTIF(C13:P13,TRUE)=0,"",COUNTIF(C13:P13,TRUE))
A14: AGW | B14: คลองลาน | C14: FALSE | D14: FALSE | E14: FALSE | F14: FALSE | G14: FALSE | H14: FALSE | I14: FALSE | J14: FALSE | K14: FALSE | L14: FALSE | M14: FALSE | N14: FALSE | O14: FALSE | P14: FALSE | Q14: =IF(COUNTIF(C14:P14,TRUE)=0,"",COUNTIF(C14:P14,TRUE))
A15: AGW | B15: เขาสวนกวาง | C15: FALSE | D15: FALSE | E15: FALSE | F15: FALSE | G15: FALSE | H15: FALSE | I15: FALSE | J15: FALSE | K15: FALSE | L15: FALSE | M15: FALSE | N15: FALSE | O15: FALSE | P15: FALSE | Q15: =IF(COUNTIF(C15:P15,TRUE)=0,"",COUNTIF(C15:P15,TRUE))
A16: AGW | B16: เขาคิชฌกูฎ | C16: FALSE | D16: FALSE | E16: FALSE | F16: FALSE | G16: FALSE | H16: FALSE | I16: FALSE | J16: FALSE | K16: FALSE | L16: FALSE | M16: FALSE | N16: FALSE | O16: FALSE | P16: FALSE | Q16: =IF(COUNTIF(C16:P16,TRUE)=0,"",COUNTIF(C16:P16,TRUE))
A17: AGW | B17: ย่านตาขาว | C17: FALSE | D17: FALSE | E17: FALSE | F17: FALSE | G17: FALSE | H17: FALSE | I17: FALSE | J17: FALSE | K17: FALSE | L17: FALSE | M17: FALSE | N17: FALSE | O17: FALSE | P17: FALSE | Q17: =IF(COUNTIF(C17:P17,TRUE)=0,"",COUNTIF(C17:P17,TRUE))
A18: AGW | B18: วังน้ำเขียว | C18: FALSE | D18: FALSE | E18: FALSE | F18: FALSE | G18: FALSE | H18: FALSE | I18: FALSE | J18: FALSE | K18: FALSE | L18: FALSE | M18: FALSE | N18: FALSE | O18: FALSE | P18: FALSE | Q18: =IF(COUNTIF(C18:P18,TRUE)=0,"",COUNTIF(C18:P18,TRUE))
... A20: AGW | B20: ดงเจริญ | C20: FALSE | D20: FALSE | E20: FALSE | F20: FALSE | G20: FALSE | H20: FALSE | I20: FALSE | J20: FALSE | K20: FALSE | L20: FALSE | M20: FALSE | N20: FALSE | O20: FALSE | P20: FALSE | Q20: =IF(COUNTIF(C20:P20,TRUE)=0,"",COUNTIF(C20:P20,TRUE))
A21: *** หมายเหตุ เช็คในช่องด้านบนเมื่อมีเหตุให้แก้ไขหรือพบข้อบกพร่อง | Q21: =SUBTOTAL(2,Q5:Q20) -> 0

Sheet Event Log
A1: System | B1: Date | C1: Online (100%) | D1: Down time(min)
A2: BSSC | B2: 46235 | C2: =IF(D2="",100,MAX(0,(1440-D2)/1440*100)) -> 100
A3: BSSC | B3: 46236 | C3: =IF(D3="",100,MAX(0,(1440-D3)/1440*100)) -> 100
A4: BSSC | B4: 46237 | C4: =IF(D4="",100,MAX(0,(1440-D4)/1440*100)) -> 99.305556 | D4: 10
A5: BSSC | B5: 46238 | C5: =IF(D5="",100,MAX(0,(1440-D5)/1440*100)) -> 100
A6: BSSC | B6: 46239 | C6: =IF(D6="",100,MAX(0,(1440-D6)/1440*100)) -> 99.513889 | D6: =RANDBETWEEN(0,10) -> 7
A7: BSSC | B7: 46240 | C7: =IF(D7="",100,MAX(0,(1440-D7)/1440*100)) -> 99.861111 | D7: =RANDBETWEEN(0,10) -> 2
A8: BSSC | B8: 46241 | C8: =IF(D8="",100,MAX(0,(1440-D8)/1440*100)) -> 99.930556 | D8: =RANDBETWEEN(0,10) -> 1
A9: BSSC | B9: 46242 | C9: =IF(D9="",100,MAX(0,(1440-D9)/1440*100)) -> 99.861111 | D9: =RANDBETWEEN(0,10) -> 2
A10: BSSC | B10: 46243 | C10: =IF(D10="",100,MAX(0,(1440-D10)/1440*100)) -> 100
A11: BSSC | B11: 46244 | C11: =IF(D11="",100,MAX(0,(1440-D11)/1440*100)) -> 99.375 | D11: =RANDBETWEEN(0,10) -> 9
A12: BSSC | B12: 46245 | C12: =IF(D12="",100,MAX(0,(1440-D12)/1440*100)) -> 100
A13: BSSC | B13: 46246 | C13: =IF(D13="",100,MAX(0,(1440-D13)/1440*100)) -> 99.444444 | D13: =RANDBETWEEN(0,10) -> 8
A14: BSSC | B14: 46247 | C14: =IF(D14="",100,MAX(0,(1440-D14)/1440*100)) -> 99.583333 | D14: =RANDBETWEEN(0,10) -> 6
A15: BSSC | B15: 46248 | C15: =IF(D15="",100,MAX(0,(1440-D15)/1440*100)) -> 100
A16: BSSC | B16: 46249 | C16: =IF(D16="",100,MAX(0,(1440-D16)/1440*100)) -> 100 | D16: =RANDBETWEEN(0,10) -> 0
A17: BSSC | B17: 46250 | C17: =IF(D17="",100,MAX(0,(1440-D17)/1440*100)) -> 99.444444 | D17: =RANDBETWEEN(0,10) -> 8
A18: BSSC | B18: 46251 | C18: =IF(D18="",100,MAX(0,(1440-D18)/1440*100)) -> 100
A19: BSSC | B19: 46252 | C19: =IF(D19="",100,MAX(0,(1440-D19)/1440*100)) -> 99.305556 | D19: =RANDBETWEEN(0,10) -> 10
A20: BSSC | B20: 46253 | C20: =IF(D20="",100,MAX(0,(1440-D20)/1440*100)) -> 100
A21: BSSC | B21: 46254 | C21: =IF(D21="",100,MAX(0,(1440-D21)/1440*100)) -> 99.791667 | D21: =RANDBETWEEN(0,10) -> 3
A22: BSSC | B22: 46255 | C22: =IF(D22="",100,MAX(0,(1440-D22)/1440*100)) -> 99.444444 | D22: =RANDBETWEEN(0,10) -> 8
A23: BSSC | B23: 46256 | C23: =IF(D23="",100,MAX(0,(1440-D23)/1440*100)) -> 99.861111 | D23: =RANDBETWEEN(0,10) -> 2
A24: BSSC | B24: 46257 | C24: =IF(D24="",100,MAX(0,(1440-D24)/1440*100)) -> 99.583333 | D24: =RANDBETWEEN(0,10) -> 6
A25: BSSC | B25: 46258 | C25: =IF(D25="",100,MAX(0,(1440-D25)/1440*100)) -> 99.791667 | D25: =RANDBETWEEN(0,10) -> 3
A26: BSSC | B26: 46259 | C26: =IF(D26="",100,MAX(0,(1440-D26)/1440*100)) -> 99.305556 | D26: =RANDBETWEEN(0,10) -> 10
A27: BSSC | B27: 46260 | C27: =IF(D27="",100,MAX(0,(1440-D27)/1440*100)) -> 99.930556 | D27: =RANDBETWEEN(0,10) -> 1
A28: BSSC | B28: 46261 | C28: =IF(D28="",100,MAX(0,(1440-D28)/1440*100)) -> 99.375 | D28: =RANDBETWEEN(0,10) -> 9
A29: BSSC | B29: 46262 | C29: =IF(D29="",100,MAX(0,(1440-D29)/1440*100)) -> 99.722222 | D29: =RANDBETWEEN(0,10) -> 4
A30: BSSC | B30: 46263 | C30: =IF(D30="",100,MAX(0,(1440-D30)/1440*100)) -> 99.652778 | D30: =RANDBETWEEN(0,10) -> 5
A31: BSSC | B31: 46264 | C31: =IF(D31="",100,MAX(0,(1440-D31)/1440*100)) -> 100 | D31: =RANDBETWEEN(0,10) -> 0
A32: BSSC | B32: 46265 | C32: =IF(D32="",100,MAX(0,(1440-D32)/1440*100)) -> 99.930556 | D32: =RANDBETWEEN(0,10) -> 1
A33: SD-WAN | B33: 46235 | C33: =IF(D33="",100,MAX(0,(1440-D33)/1440*100)) -> 100 | D33: =RANDBETWEEN(0,10) -> 0
A34: SD-WAN | B34: 46236 | C34: =IF(D34="",100,MAX(0,(1440-D34)/1440*100)) -> 100
A35: SD-WAN | B35: 46237 | C35: =IF(D35="",100,MAX(0,(1440-D35)/1440*100)) -> 100
A36: SD-WAN | B36: 46238 | C36: =IF(D36="",100,MAX(0,(1440-D36)/1440*100)) -> 99.513889 | D36: =RANDBETWEEN(0,10) -> 7
A37: SD-WAN | B37: 46239 | C37: =IF(D37="",100,MAX(0,(1440-D37)/1440*100)) -> 99.930556 | D37: =RANDBETWEEN(0,10) -> 1
A38: SD-WAN | B38: 46240 | C38: =IF(D38="",100,MAX(0,(1440-D38)/1440*100)) -> 99.305556 | D38: =RANDBETWEEN(0,10) -> 10
A39: SD-WAN | B39: 46241 | C39: =IF(D39="",100,MAX(0,(1440-D39)/1440*100)) -> 100
A40: SD-WAN | B40: 46242 | C40: =IF(D40="",100,MAX(0,(1440-D40)/1440*100)) -> 100
...
