Workbook
Name __xlnm.Print_Area_3: #REF!
Name __xlnm.Print_Area_3: #REF!
Name __xlnm.Print_Area_4: #REF!
Name IP_PBX: #REF!
Name IP_PBX: #REF!
Name OLE_LINK1: #REF!
Name Type: #REF!
Name Type: #REF!

Sheet Summary
D1: การจัดซื้ออุปกรณ์พร้อมดำเนินการติดตั้ง โครงการเพิ่มประสิทธิภาพระบบโครงข่ายสื่อสารด้วยอุปกรณ์ทวนสัญญาณผ่านคลื่นความถี่สูง (SHF) เพื่อสนับสนุนการปฏิบัติราชการและแก้ไขปัญหาให้กับประชาชนในพื้นที่ห่างไกล สัญญาเลขที่ ๘๖๘๐๒๒๘ ลงวันที่ ๒๓ กรกฎาคม ๒๕๖๘
B3: รายงานสรุปสถานะระบบชุมสายประจำวัน / DAILY SYSTEM STATUS REPORT
B4: วันที่ | C4: =TODAY() -> 46275
B5: ภาพรวมสถานะบริการทั้งระบบ
B6: ระบบศูนย์ควบคุมสถานีแม่ข่าย / Base Station Switching Center | F6: ระบบบริหารจัดการ (iMaster NCE Campus) / SD-WAN Controller | J6: ระบบบริหารจัดการชุดอุปกรณ์ทวนสัญญาณผ่านคลื่นความถี่สูง (iMaster NCE-T) / Microwave | N6: ชุดสั่งการ / Dispatcher
B7: =" สถานะ : "&Overview!$W$3 -> สถานะ : ปกติ / Normal | F7: =" สถานะ : "&Overview!$W$4 -> สถานะ : ปกติ / Normal | J7: =" สถานะ : "&Overview!$W$5 -> สถานะ : ปกติ / Normal | N7: =" สถานะ : "&Overview!$W$6 -> สถานะ : ปกติ / Normal
B9: สรุปงาน
B10: หัวข้อ | F10: ผลตรวจสอบ / Result | J10: ข้อความสรุป
B11: สถานะระบบรวม / Overall system status | F11: =IF(COUNTIF(Overview!$W$3:$W$6,"ขัดข้อง / Down")=0,"ปกติ / Normal","มีเหตุขัดข้อง / Down") -> ปกติ / Normal | J11: =IF(COUNTIF(Overview!$W$3:$W$5,"Down / ขัดข้อง")=0,"ระบบให้บริการตามปกติ / All systems operate normally","Action required: see system status sheet / มีระบบที่ต้องเร่งตรวจสอบ โปรดดูชีตข้อมูลสถานะระบบ") -> ระบบให้บริการตามปกติ / All systems operate normally
B12: รายการตรวจสอบสถานีปลายทาง / Station checks | F12: =COUNTA(Overview!$A$5:$A$20)&" จุด " -> 16 จุด | J12: ตรวจสอบสถานีและอุปกรณ์ตามรายการรายวัน / Station and equipment monitoring completed
B13: รายการรอแก้ไข / Pending corrections | F13: =Overview!$Q21&" รายการ / items" -> 0 รายการ / items | J13: =IF(Overview!$Q21=0,"ไม่มีรายการรอแก้ไข / No pending","มีรายการติดตามในชีตรายละเอียดจุดตรวจสอบ / See Station Details for follow-up") -> ไม่มีรายการรอแก้ไข / No pending

Sheet Overview
A1: รายละเอียดผลการตรวจสอบสถานีและอุปกรณ์ชุมสาย / STATION & EQUIPMENT CHECK DETAILS | T1: ข้อมูลสถานะระบบ /SYSTEM STATUS INPUT
A2: ลำดับ | B2: ชื่อสถานี | C2: ไฟฟ้า | D2: สถานีแม่ข่าย | H2: อุปกรณ์กระจายสัญญาณ | K2: SD-WAN | M2: Microwave | O2: LINK | Q2: กำลังรอการแก้ไข | R2: หมายเหตุ | T2: No. / ลำดับ | U2: System / ระบบ | V2: Monitoring scope / ขอบเขตการตรวจสอบ | W2: Status / สถานะ | X2: Customer message / ข้อความสำหรับแจ้งลูกค้า | Y2: ปรับปรุงล่าสุด / Updated
C3: Electric | D3: VSWR > 1.5 | E3: Tx | F3: Rx | G3: Down | H3: CPRI Cable | I3: SFP | J3: Down | K3: Not stable | L3: Down | M3: Not stable | N3: Down | O3: Not stable | P3: Down | T3: 1 | U3: BSSC | V3: ระบบศูนย์ควบคุมสถานีแม่ข่าย (Base Station Switching Center) | W3: ปกติ / Normal | X3: ให้บริการตามปกติ ไม่พบเหตุขัดข้อง / Normal operation; no incident found
A4: =SUBTOTAL(3,A5:A20) -> 16 | B4: =SUBTOTAL(3,B5:B30) -> 16 | C4: =SUBTOTAL(2,C5:C30) -> 0 | D4: =SUBTOTAL(2,D5:D30) -> 0 | E4: =SUBTOTAL(2,E5:E30) -> 0 | F4: =SUBTOTAL(2,F5:F30) -> 0 | G4: =SUBTOTAL(2,G5:G30) -> 0 | H4: =SUBTOTAL(2,H5:H30) -> 0 | I4: =SUBTOTAL(2,I5:I30) -> 0 | J4: =SUBTOTAL(2,J5:J30) -> 0 | ... P4: =SUBTOTAL(2,P5:P30) -> 0 | Q4: 0 | T4: 2 | U4: SD-WAN | V4: ระบบบริหารจัดการ (iMaster NCE Campus) | W4: ปกติ / Normal | X4: ให้บริการตามปกติ ไม่พบเหตุขัดข้อง / Normal operation; no incident found
A5: BS-261 | B5: BS หนองนกแก้ว | C5: FALSE | D5: FALSE | E5: FALSE | F5: FALSE | G5: FALSE | H5: FALSE | I5: FALSE | J5: FALSE | K5: FALSE | L5: FALSE | M5: FALSE | N5: FALSE | O5: FALSE | P5: FALSE | Q5: =IF(COUNTIF(C5:P5,TRUE)=0,"",COUNTIF(C5:P5,TRUE)) | T5: 3 | U5: Microwave | V5: ระบบบริหารจัดการชุดอุปกรณ์ทวนสัญญาณผ่านคลื่นความถี่สูง (iMaster NCE-T) | W5: ปกติ / Normal | X5: ให้บริการตามปกติ ไม่พบเหตุขัดข้อง / Normal operation; no incident found
A6: BS-262 | B6: BS ศรีสุขสำราญ | C6: FALSE | D6: FALSE | E6: FALSE | F6: FALSE | G6: FALSE | H6: FALSE | I6: FALSE | J6: FALSE | K6: FALSE | L6: FALSE | M6: FALSE | N6: FALSE | O6: FALSE | P6: FALSE | Q6: =IF(COUNTIF(C6:P6,TRUE)=0,"",COUNTIF(C6:P6,TRUE)) | T6: 4 | U6: Dispatcher | V6: ชุดสั่งการ | W6: ปกติ / Normal | X6: ให้บริการตามปกติ ไม่พบเหตุขัดข้อง / Normal operation; no incident found
A7: BS-263 | B7: BS คลองป่าหมู | C7: FALSE | D7: FALSE | E7: FALSE | F7: FALSE | G7: FALSE | H7: FALSE | I7: FALSE | J7: FALSE | K7: FALSE | L7: FALSE | M7: FALSE | N7: FALSE | O7: FALSE | P7: FALSE | Q7: =IF(COUNTIF(C7:P7,TRUE)=0,"",COUNTIF(C7:P7,TRUE)) | T7: Base station 8 station | U7: จำนวน
A8: BS-264 | B8: BS วัดบางอุดม | C8: FALSE | D8: FALSE | E8: FALSE | F8: FALSE | G8: FALSE | H8: FALSE | I8: FALSE | J8: FALSE | K8: FALSE | L8: FALSE | M8: FALSE | N8: FALSE | O8: FALSE | P8: FALSE | Q8: =IF(COUNTIF(C8:P8,TRUE)=0,"",COUNTIF(C8:P8,TRUE)) | T8: Online | U8: =COUNTBLANK(Q5:Q12) -> 8
A9: BS-265 | B9: BS วังงิ้ว | C9: FALSE | D9: FALSE | E9: FALSE | F9: FALSE | G9: FALSE | H9: FALSE | I9: FALSE | J9: FALSE | K9: FALSE | L9: FALSE | M9: FALSE | N9: FALSE | O9: FALSE | P9: FALSE | Q9: =IF(COUNTIF(C9:P9,TRUE)=0,"",COUNTIF(C9:P9,TRUE)) | T9: Pending | U9: =ROWS(Q5:Q12)-COUNTBLANK(Q5:Q12) -> 0
A10: BS-266 | B10: BS บ้านปางใหม่พัฒนา | C10: FALSE | D10: FALSE | E10: FALSE | F10: FALSE | G10: FALSE | H10: FALSE | I10: FALSE | J10: FALSE | K10: FALSE | L10: FALSE | M10: FALSE | N10: FALSE | O10: FALSE | P10: FALSE | Q10: =IF(COUNTIF(C10:P10,TRUE)=0,"",COUNTIF(C10:P10,TRUE)) | T10: Analog Gateway 8 station | U10: จำนวน
A11: BS-267 | B11: BS ช่อง | C11: FALSE | D11: FALSE | E11: FALSE | F11: FALSE | G11: FALSE | H11: FALSE | I11: FALSE | J11: FALSE | K11: FALSE | L11: FALSE | M11: FALSE | N11: FALSE | O11: FALSE | P11: FALSE | Q11: =IF(COUNTIF(C11:P11,TRUE)=0,"",COUNTIF(C11:P11,TRUE)) | T11: Online | U11: =COUNTBLANK(Q13:Q20) -> 8
A12: BS-268 | B12: BS คลองพลู | C12: FALSE | D12: FALSE | E12: FALSE | F12: FALSE | G12: FALSE | H12: FALSE | I12: FALSE | J12: FALSE | K12: FALSE | L12: FALSE | M12: FALSE | N12: FALSE | O12: FALSE | P12: FALSE | Q12: =IF(COUNTIF(C12:P12,TRUE)=0,"",COUNTIF(C12:P12,TRUE)) | T12: Pending | U12: =ROWS(Q13:Q20)-COUNTBLANK(Q13:Q20) -> 0
A13: AGW | B13: ห้วยกระเจา | C13: FALSE | D13: FALSE | E13: FALSE | F13: FALSE | G13: FALSE | H13: FALSE | I13: FALSE | J13: FALSE | K13: FALSE | L13: FALSE | M13: FALSE | N13: FALSE | O13: FALSE | P13: FALSE | Q13: =IF(COUNTIF(C13:P13,TRUE)=0,"",COUNTIF(C13:P13,TRUE))
A14: AGW | B14: คลองลาน | C14: FALSE | D14: FALSE | E14: FALSE | F14: FALSE | G14: FALSE | H14: FALSE | I14: FALSE | J14: FALSE | K14: FALSE | L14: FALSE | M14: FALSE | N14: FALSE | O14: FALSE | P14: FALSE | Q14: =IF(COUNTIF(C14:P14,TRUE)=0,"",COUNTIF(C14:P14,TRUE))
A15: AGW | B15: เขาสวนกวาง | C15: FALSE | D15: FALSE | E15: FALSE | F15: FALSE | G15: FALSE | H15: FALSE | I15: FALSE | J15: FALSE | K15: FALSE | L15: FALSE | M15: FALSE | N15: FALSE | O15: FALSE | P15: FALSE | Q15: =IF(COUNTIF(C15:P15,TRUE)=0,"",COUNTIF(C15:P15,TRUE))
A16: AGW | B16: เขาคิชฌกูฎ | C16: FALSE | D16: FALSE | E16: FALSE | F16: FALSE | G16: FALSE | H16: FALSE | I16: FALSE | J16: FALSE | K16: FALSE | L16: FALSE | M16: FALSE | N16: FALSE | O16: FALSE | P16: FALSE | Q16: =IF(COUNTIF(C16:P16,TRUE)=0,"",COUNTIF(C16:P16,TRUE))
A17: AGW | B17: ย่านตาขาว | C17: FALSE | D17: FALSE | E17: FALSE | F17: FALSE | G17: FALSE | H17: FALSE | I17: FALSE | J17: FALSE | K17: FALSE | L17: FALSE | M17: FALSE | N17: FALSE | O17: FALSE | P17: FALSE | Q17: =IF(COUNTIF(C17:P17,TRUE)=0,"",COUNTIF(C17:P17,TRUE))
A18: AGW | B18: วังน้ำเขียว | C18: FALSE | D18: FALSE | E18: FALSE | F18: FALSE | G18: FALSE | H18: FALSE | I18: FALSE | J18: FALSE | K18: FALSE | L18: FALSE | M18: FALSE | N18: FALSE | O18: FALSE | P18: FALSE | Q18: =IF(COUNTIF(C18:P18,TRUE)=0,"",COUNTIF(C18:P18,TRUE))
A19: AGW | B19: หัวไทร | C19: FALSE | D19: FALSE | E19: FALSE | F19: FALSE | G19: FALSE | H19: FALSE | I19: FALSE | J19: FALSE | K19: FALSE | L19: FALSE | M19: FALSE | N19: FALSE | O19: FALSE | P19: FALSE | Q19: =IF(COUNTIF(C19:P19,TRUE)=0,"",COUNTIF(C19:P19,TRUE))
A20: AGW | B20: ดงเจริญ | C20: FALSE | D20: FALSE | E20: FALSE | F20: FALSE | G20: FALSE | H20: FALSE | I20: FALSE | J20: FALSE | K20: FALSE | L20: FALSE | M20: FALSE | N20: FALSE | O20: FALSE | P20: FALSE | Q20: =IF(COUNTIF(C20:P20,TRUE)=0,"",COUNTIF(C20:P20,TRUE))
A21: *** หมายเหตุ เช็คในช่องด้านบนเมื่อมีเหตุให้แก้ไขหรือพบข้อบกพร่อง | Q21: =SUBTOTAL(2,Q5:Q20) -> 0

Sheet Event Log
A1: System | B1: Date | C1: Online (100%) | D1: Down time(min)
A2: BSSC | B2: 46235 | C2: =IF(D2="",100,MAX(0,(1440-D2)/1440*100)) -> 100
A3: BSSC | B3: 46236 | C3: =IF(D3="",100,MAX(0,(1440-D3)/1440*100)) -> 100
A4: BSSC | B4: 46237 | C4: =IF(D4="",100,MAX(0,(1440-D4)/1440*100)) -> 100
A5: BSSC | B5: 46238 | C5: =IF(D5="",100,MAX(0,(1440-D5)/1440*100)) -> 100
A6: BSSC | B6: 46239 | C6: =IF(D6="",100,MAX(0,(1440-D6)/1440*100)) -> 100
A7: BSSC | B7: 46240 | C7: =IF(D7="",100,MAX(0,(1440-D7)/1440*100)) -> 100
A8: BSSC | B8: 46241 | C8: =IF(D8="",100,MAX(0,(1440-D8)/1440*100)) -> 99.791667 | D8: 3
A9: BSSC | B9: 46242 | C9: =IF(D9="",100,MAX(0,(1440-D9)/1440*100)) -> 100
A10: BSSC | B10: 46243 | C10: =IF(D10="",100,MAX(0,(1440-D10)/1440*100)) -> 100
A11: BSSC | B11: 46244 | C11: =IF(D11="",100,MAX(0,(1440-D11)/1440*100)) -> 100
A12: BSSC | B12: 46245 | C12: =IF(D12="",100,MAX(0,(1440-D12)/1440*100)) -> 100
A13: BSSC | B13: 46246 | C13: =IF(D13="",100,MAX(0,(1440-D13)/1440*100)) -> 100
A14: BSSC | B14: 46247 | C14: =IF(D14="",100,MAX(0,(1440-D14)/1440*100)) -> 100
A15: BSSC | B15: 46248 | C15: =IF(D15="",100,MAX(0,(1440-D15)/1440*100)) -> 100
A16: BSSC | B16: 46249 | C16: =IF(D16="",100,MAX(0,(1440-D16)/1440*100)) -> 100
A17: BSSC | B17: 46250 | C17: =IF(D17="",100,MAX(0,(1440-D17)/1440*100)) -> 100
A18: BSSC | B18: 46251 | C18: =IF(D18="",100,MAX(0,(1440-D18)/1440*100)) -> 100
A19: BSSC | B19: 46252 | C19: =IF(D19="",100,MAX(0,(1440-D19)/1440*100)) -> 100
A20: BSSC | B20: 46253 | C20: =IF(D20="",100,MAX(0,(1440-D20)/1440*100)) -> 100
... A31: BSSC | B31: 46264 | C31: =IF(D31="",100,MAX(0,(1440-D31)/1440*100)) -> 100
A32: BSSC | B32: 46265 | C32: =IF(D32="",100,MAX(0,(1440-D32)/1440*100)) -> 99.722222 | D32: 4
A33: SD-WAN | B33: 46235 | C33: =IF(D33="",100,MAX(0,(1440-D33)/1440*100)) -> 100
A34: SD-WAN | B34: 46236 | C34: =IF(D34="",100,MAX(0,(1440-D34)/1440*100)) -> 100
A35: SD-WAN | B35: 46237 | C35: =IF(D35="",100,MAX(0,(1440-D35)/1440*100)) -> 100
A36: SD-WAN | B36: 46238 | C36: =IF(D36="",100,MAX(0,(1440-D36)/1440*100)) -> 100
A37: SD-WAN | B37: 46239 | C37: =IF(D37="",100,MAX(0,(1440-D37)/1440*100)) -> 100
A38: SD-WAN | B38: 46240 | C38: =IF(D38="",100,MAX(0,(1440-D38)/1440*100)) -> 100
A39: SD-WAN | B39: 46241 | C39: =IF(D39="",100,MAX(0,(1440-D39)/1440*100)) -> 100
A40: SD-WAN | B40: 46242 | C40: =IF(D40="",100,MAX(0,(1440-D40)/1440*100)) -> 100
A41: SD-WAN | B41: 46243 | C41: =IF(D41="",100,MAX(0,(1440-D41)/1440*100)) -> 100
A42: SD-WAN | B42: 46244 | C42: =IF(D42="",100,MAX(0,(1440-D42)/1440*100)) -> 100
A43: SD-WAN | B43: 46245 | C43: =IF(D43="",100,MAX(0,(1440-D43)/1440*100)) -> 100
A44: SD-WAN | B44: 46246 | C44: =IF(D44="",100,MAX(0,(1440-D44)/1440*100)) -> 100
... A66: Microwave | B66: 46237 | C66: =IF(D66="",100,MAX(0,(1440-D66)/1440*100)) -> 100
A67: Microwave | B67: 46238 | C67: =IF(D67="",100,MAX(0,(1440-D67)/1440*100)) -> 99.652778 | D67: 5
A68: Microwave | B68: 46239 | C68: =IF(D68="",100,MAX(0,(1440-D68)/1440*100)) -> 100
A69: Microwave | B69: 46240 | C69: =IF(D69="",100,MAX(0,(1440-D69)/1440*100)) -> 100
A70: Microwave | B70: 46241 | C70: =IF(D70="",100,MAX(0,(1440-D70)/1440*100)) -> 100
A71: Microwave | B71: 46242 | C71: =IF(D71="",100,MAX(0,(1440-D71)/1440*100)) -> 100
...

Sheet วิเคราะห์ข้อมูล
A1: วิเคราะห์สถานะระบบและสถานี | SYSTEM OPERATIONS INSIGHTS
A3: ="ข้อมูล ณ "&TEXT(Summary!C4,"d mmmm yyyy")&" | ครอบคลุม 4 ระบบ, 16 สถานี และบันทึกรายวัน 124 รายการ" -> ข้อมูล ณ 10 September 2026 | ครอบคลุม 4 ระบบ, 16 สถานี และบันทึกรายวัน 124 รายการ
A5: ความพร้อมใช้งานเฉลี่ย | D5: เวลาหยุดรวม | G5: วัน-ระบบที่ Online 100% | J5: สถานีที่ต้องติดตาม
A6: =AVERAGE('Event Log'!C2:C125) -> 99.987679 | D6: =SUM('Event Log'!D2:D125) -> 22 | G6: =COUNTIF('Event Log'!D2:D125,0) -> 0 | J6: =Overview!Q21 -> 0
A9: =IF(Overview!Q21>0,"ประเด็นสำคัญ: บริการทั้ง 4 ระบบรายงานสถานะปกติ แต่มี "&Overview!Q21&" สถานีที่ต้องติดตาม โดยทั้งหมดถูกทำเครื่องหมาย VSWR > 1.5","ไม่พบรายการติดตามสถานี") -> ไม่พบรายการติดตามสถานี
A12: สรุปประสิทธิภาพรายระบบ | AUGUST 2026 | G12: ข้อค้นพบเบื้องต้น | INITIAL INSIGHTS
A13: ระบบ | B13: Online เฉลี่ย | C13: Downtime (นาที) | D13: Online 100% | E13: ต่ำกว่า 99.80% | F13: Downtime สูงสุด | G13: ="1) ข้อมูลเป็นแบบจำลอง: Downtime ใน Event Log ใช้ RANDBETWEEN(0,5) จึงเปลี่ยนทุกครั้งที่ Excel คำนวณใหม่" -> 1) ข้อมูลเป็นแบบจำลอง: Downtime ใน Event Log ใช้ RANDBETWEEN(0,5) จึงเปลี่ยนทุกครั้งที่ Excel คำนวณใหม่
A14: BSSC | B14: =AVERAGEIF('Event Log'!$A$2:$A$125,A14,'Event Log'!$C$2:$C$125) -> 99.984319 | C14: =SUMIF('Event Log'!$A$2:$A$125,A14,'Event Log'!$D$2:$D$125) -> 7 | D14: =COUNTIFS('Event Log'!$A$2:$A$125,A14,'Event Log'!$D$2:$D$125,0) -> 0 | E14: =COUNTIFS('Event Log'!$A$2:$A$125,A14,'Event Log'!$C$2:$C$125,"<99.8") -> 2 | F14: =_xlfn.MAXIFS('Event Log'!$D$2:$D$125,'Event Log'!$A$2:$A$125,A14) -> 4 | G14: ="2) Online เฉลี่ยสูงสุดขณะนี้: "&INDEX($A$14:$A$17,MATCH(MAX($B$14:$B$17),$B$14:$B$17,0))&" ("&TEXT(MAX($B$14:$B$17),"0.00\%")&")" -> 2) Online เฉลี่ยสูงสุดขณะนี้: SD-WAN (100.00%)
A15: SD-WAN | B15: =AVERAGEIF('Event Log'!$A$2:$A$125,A15,'Event Log'!$C$2:$C$125) -> 100 | C15: =SUMIF('Event Log'!$A$2:$A$125,A15,'Event Log'!$D$2:$D$125) -> 0 | D15: =COUNTIFS('Event Log'!$A$2:$A$125,A15,'Event Log'!$D$2:$D$125,0) -> 0 | E15: =COUNTIFS('Event Log'!$A$2:$A$125,A15,'Event Log'!$C$2:$C$125,"<99.8") -> 0 | F15: =_xlfn.MAXIFS('Event Log'!$D$2:$D$125,'Event Log'!$A$2:$A$125,A15) -> 0 | G15: ="3) Downtime สะสมสูงสุดขณะนี้: "&INDEX($A$14:$A$17,MATCH(MAX($C$14:$C$17),$C$14:$C$17,0))&" ("&MAX($C$14:$C$17)&" นาที)" -> 3) Downtime สะสมสูงสุดขณะนี้: Dispatcher (10 นาที)
A16: Microwave | B16: =AVERAGEIF('Event Log'!$A$2:$A$125,A16,'Event Log'!$C$2:$C$125) -> 99.988799 | C16: =SUMIF('Event Log'!$A$2:$A$125,A16,'Event Log'!$D$2:$D$125) -> 5 | D16: =COUNTIFS('Event Log'!$A$2:$A$125,A16,'Event Log'!$D$2:$D$125,0) -> 0 | E16: =COUNTIFS('Event Log'!$A$2:$A$125,A16,'Event Log'!$C$2:$C$125,"<99.8") -> 1 | F16: =_xlfn.MAXIFS('Event Log'!$D$2:$D$125,'Event Log'!$A$2:$A$125,A16) -> 5 | G16: ="4) สถานี "&Overview!Q21&"/"&COUNTA(Overview!A5:A20)&" แห่งถูกทำเครื่องหมาย VSWR > 1.5; ควรตรวจสายอากาศ/ฟีดเดอร์หรือเกณฑ์การบันทึก" -> 4) สถานี 0/16 แห่งถูกทำเครื่องหมาย VSWR > 1.5; ควรตรวจสายอากาศ/ฟีดเดอร์หรือเกณฑ์การบันทึก
A17: Dispatcher | B17: =AVERAGEIF('Event Log'!$A$2:$A$125,A17,'Event Log'!$C$2:$C$125) -> 99.977599 | C17: =SUMIF('Event Log'!$A$2:$A$125,A17,'Event Log'!$D$2:$D$125) -> 10 | D17: =COUNTIFS('Event Log'!$A$2:$A$125,A17,'Event Log'!$D$2:$D$125,0) -> 0 | E17: =COUNTIFS('Event Log'!$A$2:$A$125,A17,'Event Log'!$C$2:$C$125,"<99.8") -> 1 | F17: =_xlfn.MAXIFS('Event Log'!$D$2:$D$125,'Event Log'!$A$2:$A$125,A17) -> 10 | G17: ="5) แม้สถานะบริการเป็น 'ปกติ' แต่มีรายการรอแก้ไข ควรยืนยันความสอดคล้องก่อนแจ้งผู้รับบริการ" -> 5) แม้สถานะบริการเป็น 'ปกติ' แต่มีรายการรอแก้ไข ควรยืนยันความสอดคล้องก่อนแจ้งผู้รับบริการ
A18: รวม / เฉลี่ย | B18: =AVERAGE('Event Log'!C2:C125) -> 99.987679 | C18: =SUM('Event Log'!D2:D125) -> 22 | D18: =COUNTIF('Event Log'!D2:D125,0) -> 0 | E18: =COUNTIF('Event Log'!C2:C125,"<99.8") -> 4 | F18: =MAX('Event Log'!D2:D125) -> 10
A21: รายการตรวจสถานีที่ถูกทำเครื่องหมาย
A22: ประเภท | B22: จำนวนสถานี | C22: สัดส่วน
A23: VSWR > 1.5 | B23: =COUNTIF(Overview!D5:D20,TRUE) -> 0 | C23: =B23/COUNTA(Overview!A5:A20) -> 0
A24: ข้อบกพร่องอื่น | B24: {=SUMPRODUCT(--(Overview!C5:C20=TRUE))+SUMPRODUCT(--(Overview!E5:P20=TRUE))} -> 0 | C24: =B24/COUNTA(Overview!A5:A20) -> 0
A25: ข้อจำกัดข้อมูล: ตัวเลข Online และ Downtime เป็นข้อมูลจำลองแบบสุ่ม ไม่ควรใช้เป็นหลักฐาน SLA หรือรายงานเหตุการณ์จริงจนกว่าจะเปลี่ยนเป็นข้อมูลจากระบบ Monitoring
A27: แนวโน้ม Online รายวัน (%) — ข้อมูลสำหรับกราฟ
A28: วันที่ | B28: BSSC | C28: SD-WAN | D28: Microwave | E28: Dispatcher
A29: ='Event Log'!B2 -> 46235 | B29: ='Event Log'!C2 -> 100 | C29: ='Event Log'!C33 -> 100 | D29: ='Event Log'!C64 -> 100 | E29: ='Event Log'!C95 -> 100
A30: ='Event Log'!B3 -> 46236 | B30: ='Event Log'!C3 -> 100 | C30: ='Event Log'!C34 -> 100 | D30: ='Event Log'!C65 -> 100 | E30: ='Event Log'!C96 -> 100
A31: ='Event Log'!B4 -> 46237 | B31: ='Event Log'!C4 -> 100 | C31: ='Event Log'!C35 -> 100 | D31: ='Event Log'!C66 -> 100 | E31: ='Event Log'!C97 -> 99.305556
A32: ='Event Log'!B5 -> 46238 | B32: ='Event Log'!C5 -> 100 | C32: ='Event Log'!C36 -> 100 | D32: ='Event Log'!C67 -> 99.652778 | E32: ='Event Log'!C98 -> 100
A33: ='Event Log'!B6 -> 46239 | B33: ='Event Log'!C6 -> 100 | C33: ='Event Log'!C37 -> 100 | D33: ='Event Log'!C68 -> 100 | E33: ='Event Log'!C99 -> 100
A34: ='Event Log'!B7 -> 46240 | B34: ='Event Log'!C7 -> 100 | C34: ='Event Log'!C38 -> 100 | D34: ='Event Log'!C69 -> 100 | E34: ='Event Log'!C100 -> 100
A35: ='Event Log'!B8 -> 46241 | B35: ='Event Log'!C8 -> 99.791667 | C35: ='Event Log'!C39 -> 100 | D35: ='Event Log'!C70 -> 100 | E35: ='Event Log'!C101 -> 100
A36: ='Event Log'!B9 -> 46242 | B36: ='Event Log'!C9 -> 100 | C36: ='Event Log'!C40 -> 100 | D36: ='Event Log'!C71 -> 100 | E36: ='Event Log'!C102 -> 100
A37: ='Event Log'!B10 -> 46243 | B37: ='Event Log'!C10 -> 100 | C37: ='Event Log'!C41 -> 100 | D37: ='Event Log'!C72 -> 100 | E37: ='Event Log'!C103 -> 100
A38: ='Event Log'!B11 -> 46244 | B38: ='Event Log'!C11 -> 100 | C38: ='Event Log'!C42 -> 100 | D38: ='Event Log'!C73 -> 100 | E38: ='Event Log'!C104 -> 100
A39: ='Event Log'!B12 -> 46245 | B39: ='Event Log'!C12 -> 100 | C39: ='Event Log'!C43 -> 100 | D39: ='Event Log'!C74 -> 100 | E39: ='Event Log'!C105 -> 100
A40: ='Event Log'!B13 -> 46246 | B40: ='Event Log'!C13 -> 100 | C40: ='Event Log'!C44 -> 100 | D40: ='Event Log'!C75 -> 100 | E40: ='Event Log'!C106 -> 100
... A59: ='Event Log'!B32 -> 46265 | B59: ='Event Log'!C32 -> 99.722222 | C59: ='Event Log'!C63 -> 100 | D59: ='Event Log'!C94 -> 100 | E59: ='Event Log'!C125 -> 100
